Workbook

Sheet Read Me
A1: Mobile Charging Repair Simulation - Asset Production Register
A2: Source: 'Mobile charging repair Simulation' storyboard (16pp, modules BC.1 / BC.2 / BC.3). Prepared 21 Aug 2026.
A4: THE DECISION RULE
A5: BLENDER - if the learner must IDENTIFY, LOCATE, ORIENT or MANIPULATE the thing with their hands.
A6: Spatial understanding transfers to a real bench. 65 rows (48 models/effects + 17 animation clips), 87.5 days.
A7: INFOGRAPHIC - if the content is INVISIBLE signal flow, electrical logic, a numeric spec, a named
A8: sequence, or a comparison. 3D adds cost and teaches nothing extra here. 28 graphics, 21 days.
A9: PHOTO/VIDEO - real-world defects and already-sourced footage. 7 items, nearly all already supplied.
A10: RUNTIME/CODE - interaction, state and scoring. Not an art deliverable at all. 7 items, 13.5 days.
A12: THE THREE THINGS THAT MATTER MOST IN THIS BREAKDOWN
A13: 1. This course is ONE phone teardown, reused 18 times. B02 (mainboard) appears in 7 of 18 scenes;
A14: B05 (USB-C port) in 5; B28 (hot air station) in 6. Build the master assets to a high standard once.
... A57: 9 rows are High complexity and carry 26 days between them - staff those first: B02, B05, B10, B11, B45, A09, A12, U02, U04.

Sheet Asset Register
A1: Asset Register - every visual asset the storyboard calls for
A2: One row per distinct asset. Colour = production route. Filter column D to split the work.
A4: Asset ID | B4: Asset name | C4: Module | D4: Route | E4: Scenes used in | F4: Reuse (scenes) | G4: Why this route | H4: Tri budget (LOD0) | I4: Textures | J4: Anim clips | K4: Est. days | L4: Complexity | M4: Notes / risks
A5: B01 | B5: Phone body shell + removable back cover | C5: BC.1 | D5: BLENDER | E5: BC.1-S1, BC.3-S1, BC.3-S7 | F5: =LEN(E5)-LEN(SUBSTITUTE(E5,",",""))+1 -> 3 | G5: Learner must orient the handset in their hands and know which way it opens | H5: 18k | I5: 2x1K PBR | J5: 0 | K5: 3 | L5: Med | M5: Model one generic mid-range Android form factor. Back cover as separate mesh so it can be lifted.
A6: B02 | B6: Mainboard (PBA) - populated | C6: BC.1 | D6: BLENDER | E6: BC.1-S1, BC.1-S4, BC.3-S2, BC.3-S3, BC.3-S4, BC.3-S5, BC.3-S6 | F6: =LEN(E6)-LEN(SUBSTITUTE(E6,",",""))+1 -> 7 | G6: The stage every board-level fix happens on; spatial location of each part is the lesson | H6: 45k | I6: 2K colour + 1K rough/normal | J6: 0 | K6: 4 | L6: High | M6: MASTER ASSET - highest reuse in the whole course. Build once, texture properly, never rebuild.
A7: B03 | B7: Sub-PBA / small daughterboard | C7: BC.1 | D7: BLENDER | E7: BC.1-S3, BC.3-S3 | F7: =LEN(E7)-LEN(SUBSTITUTE(E7,",",""))+1 -> 2 | G7: Storyboard NOTE says the ribbon may bond to a Sub-PBA instead - needs its own mesh | H7: 8k | I7: 1K shared atlas | J7: 0 | K7: 1 | L7: Low
A8: B04 | B8: Screw set + labelled screw tray | C8: BC.2 | D8: BLENDER | E8: BC.3-S7 | F8: =LEN(E8)-LEN(SUBSTITUTE(E8,",",""))+1 -> 1 | G8: 'Every screw in its labelled tray slot' is a physical placement habit - must be manipulable | H8: 4k | I8: 512 shared | J8: 0 | K8: 1 | L8: Low | M8: Tray slot labels as a texture, not geometry.
A9: B05 | B9: USB-C female port assembly (shell, insert, 24 pins, mounting legs, gasket) | C9: BC.1 | D9: BLENDER | E9: BC.1-S1, BC.1-S2, BC.2-S3, BC.3-S1, BC.3-S2 | F9: =LEN(E9)-LEN(SUBSTITUTE(E9,",",""))+1 -> 5 | G9: HERO. Exploded view + 180 deg cutaway + per-pin highlight all need real geometry | H9: 30k | I9: 2K + gold/steel PBR | J9: 2 | K9: 4 | L9: High | M9: Build as 5 named sub-objects so explode + pin highlight are driven by transforms, not separate models.
A10: B06 | B10: USB-C male plug (cable end) | C10: BC.1 | D10: BLENDER | E10: BC.1-S1, BC.2-S3, BC.3-S1, BC.3-S7 | F10: =LEN(E10)-LEN(SUBSTITUTE(E10,",",""))+1 -> 4 | G10: Insertion + orientation demo | H10: 6k | I10: 1K shared | J10: 0 | K10: 1 | L10: Low
A11: B07 | B11: USB-C cable (curve-deformable) | C11: BC.1 | D11: BLENDER | E11: BC.1-S1, BC.2-S3, BC.3-S7 | F11: =LEN(E11)-LEN(SUBSTITUTE(E11,",",""))+1 -> 3 | G11: Wiggle test and cable-fault checks need it to bend | H11: 3k | I11: 512 tileable | J11: 1 | K11: 1 | L11: Low | M11: Curve modifier, baked to skinned mesh for glTF export.
A12: B08 | B12: Wall charger adapter (TA) | C12: BC.1 | D12: BLENDER | E12: BC.1-S1, BC.3-S7 | F12: =LEN(E12)-LEN(SUBSTITUTE(E12,",",""))+1 -> 2 | G12: Start of the charging path; also the 'known-good TA' in every test step | H12: 5k | I12: 1K | J12: 0 | K12: 1 | L12: Low
A13: B09 | B13: Wall outlet / socket plate | C13: BC.1 | D13: BLENDER | E13: BC.1-S1 | F13: =LEN(E13)-LEN(SUBSTITUTE(E13,",",""))+1 -> 1 | G13: Anchors the path diagram in something familiar | H13: 1k | I13: 512 shared | J13: 0 | K13: 0.5 | L13: Low
A14: B10 | B14: FPC flex ribbon (rigged for bend + peel) | C14: BC.1 | D14: BLENDER | E14: BC.1-S1, BC.1-S3, BC.3-S2, BC.3-S3 | F14: =LEN(E14)-LEN(SUBSTITUTE(E14,",",""))+1 -> 4 | G14: HERO. The peel-off in Fix 3 is the single most misdiagnosed fault - must deform, not cut | H14: 6k | I14: 1K gold/polyimide | J14: 2 | K14: 3 | L14: High | M14: Bone chain or shape keys. Cloth sim will NOT export to real-time - bake it.
A15: B11 | B15: Board-side ZIF socket + hinged flap + gold pins | C15: BC.1 | D15: BLENDER | E15: BC.1-S3, BC.3-S3 | F15: =LEN(E15)-LEN(SUBSTITUTE(E15,",",""))+1 -> 2 | G15: HERO. 'Is the flap fully closed?' is the diagnosis - the flap must actually hinge | H15: 14k | I15: 2K gold/black nylon | J15: 2 | K15: 4 | L15: High | M15: Flap on its own pivot. Latched/unlatched are two states the quiz can test.
A16: B12 | B16: Stiffener backing + anchoring solder pads | C16: BC.1 | D16: BLENDER | E16: BC.1-S3, BC.3-S3 | F16: =LEN(E16)-LEN(SUBSTITUTE(E16,",",""))+1 -> 2 | G16: Named failure point (cracked/dry pads) | H16: 2k | I16: shares B11 atlas | J16: 0 | K16: 0.5 | L16: Low
A17: B13 | B17: Charger IC package + BGA solder ball array | C17: BC.1 | D17: BLENDER | E17: BC.1-S4, BC.3-S4, BC.3-S5 | F17: =LEN(E17)-LEN(SUBSTITUTE(E17,",",""))+1 -> 3 | G17: Fix 4 is entirely about the balls UNDER the chip - needs a cutaway-capable mesh | H17: 5k | I17: 1K | J17: 1 | K17: 2 | L17: Med | M17: Model the ball array. Cold-joint vs reflowed is a geometry+material variant, see B40.
A18: B14 | B18: Neighbouring SMT component kit (caps, resistors, shields) | C18: BC.1 | D18: BLENDER | E18: BC.1-S4, BC.3-S2, BC.3-S4, BC.3-S5, BC.3-S6 | F18: =LEN(E18)-LEN(SUBSTITUTE(E18,",",""))+1 -> 5 | G18: 'Without disturbing nearby components' only means something if they are there | H18: 6k | I18: 512 atlas | J18: 0 | K18: 1.5 | L18: Low | M18: Library of ~10 parts, instanced across the board. Cheap, big realism win.
A19: B15 | B19: Battery connector SOCKET (AXF361500, board side) | C19: BC.1 | D19: BLENDER | E19: BC.1-S5, BC.2-S4, BC.3-S6 | F19: =LEN(E19)-LEN(SUBSTITUTE(E19,",",""))+1 -> 3 | G19: Storyboard asks for a macro product shot AND it is the Fix 6 subject | H19: 10k | I19: 2K gold plating | J19: 1 | K19: 2 | L19: Med | M19: Gold-plating texture detail is what sells this shot. Worth a proper anisotropic material.
A20: B16 | B20: Battery connector HEADER (AXF461500, battery side) | C20: BC.1 | D20: BLENDER | E20: BC.1-S5, BC.2-S4, BC.3-S6 | F20: =LEN(E20)-LEN(SUBSTITUTE(E20,",",""))+1 -> 3 | G20: The mating half - two-part connector is the teaching point | H20: 8k | I20: shares B15 atlas | J20: 1 | K20: 2 | L20: Med
A21: B17 | B21: Li-po battery pouch + tabs + BMS flex | C21: BC.1 | D21: BLENDER | E21: BC.1-S1, BC.1-S6, BC.2-S4, BC.3-S7 | F21: =LEN(E21)-LEN(SUBSTITUTE(E21,",",""))+1 -> 4 | G21: Disconnect-first safety rule acts on this object | H21: 7k | I21: 2K aluminium laminate | J21: 1 | K21: 2 | L21: Med
A22: B18 | B22: Digital multimeter + probe leads | C22: BC.2 | D22: BLENDER | E22: BC.2-S1, BC.2-S3, BC.3-S6, BC.3-S7 | F22: =LEN(E22)-LEN(SUBSTITUTE(E22,",",""))+1 -> 4 | G22: Learner performs the voltage test - probe placement is a motor skill | H22: 9k | I22: 1K + dynamic LCD | J22: 2 | K22: 2 | L22: Med | M22: LCD is a separate material slot driven at runtime (see U02), NOT a baked number.
A23: B19 | B23: USB power meter dongle | C23: BC.2 | D23: BLENDER | E23: BC.2-S1, BC.3-S7 | F23: =LEN(E23)-LEN(SUBSTITUTE(E23,",",""))+1 -> 2 | G23: Reads the actual current - the 'is it charging slowly' test | H23: 4k | I23: 1K + dynamic display | J23: 0 | K23: 1 | L23: Low
A24: B20 | B24: Magnifying lamp | C24: BC.2 | D24: BLENDER | E24: BC.2-S1, BC.3-S1 | F24: =LEN(E24)-LEN(SUBSTITUTE(E24,",",""))+1 -> 2 | G24: Named in Fix 1 step 2 | H24: 4k | I24: 1K shared bench atlas | J24: 0 | K24: 1 | L24: Low
A25: B21 | B25: Digital (Dino) microscope | C25: BC.2 | D25: BLENDER | E25: BC.2-S1, BC.3-S1, BC.3-S2 | F25: =LEN(E25)-LEN(SUBSTITUTE(E25,",",""))+1 -> 3 | G25: 'Inspect under magnification' recurs in 5 of 6 fixes | H25: 6k | I25: 1K shared bench atlas | J25: 0 | K25: 1.5 | L25: Med
A26: B22 | B26: Precision screwdriver set | C26: BC.2 | D26: BLENDER | E26: BC.2-S1, BC.3-S7 | F26: =LEN(E26)-LEN(SUBSTITUTE(E26,",",""))+1 -> 2 | G26: Opening the phone | H26: 3k | I26: 512 shared | J26: 0 | K26: 1 | L26: Low
A27: B23 | B27: Plastic pry tools / spudger set | C27: BC.2 | D27: BLENDER | E27: BC.2-S1, BC.3-S7 | F27: =LEN(E27)-LEN(SUBSTITUTE(E27,",",""))+1 -> 2 | G27: Opening the phone without damage | H27: 2k | I27: 512 shared | J27: 0 | K27: 0.5 | L27: Low
A28: B24 | B28: Anti-static wrist band | C28: BC.2 | D28: BLENDER | E28: BC.2-S1 | F28: =LEN(E28)-LEN(SUBSTITUTE(E28,",",""))+1 -> 1 | G28: ESD discipline - visible on the bench | H28: 2k | I28: 512 shared | J28: 0 | K28: 0.5 | L28: Low
A29: B25 | B29: Anti-static mat | C29: BC.2 | D29: BLENDER | E29: BC.2-S1, BC.3-S1, BC.3-S7 | F29: =LEN(E29)-LEN(SUBSTITUTE(E29,",",""))+1 -> 3 | G29: Bench surface for every repair scene | H29: 0.5k | I29: 1K tileable | J29: 0 | K29: 0.25 | L29: Low
A30: B26 | B30: PBA holder / board fixture (articulated) | C30: BC.2 | D30: BLENDER | E30: BC.2-S1, BC.3-S2, BC.3-S3, BC.3-S4, BC.3-S5, BC.3-S6 | F30: =LEN(E30)-LEN(SUBSTITUTE(E30,",",""))+1 -> 6 | G30: 'Hands free instead of holding the board' - the board sits in this in every rework scene | H30: 8k | I30: 1K | J30: 1 | K30: 2 | L30: Med | M30: Jaws need to open/close if you want the 'clamp the board' beat.
A31: B27 | B31: Soldering iron + stand | C31: BC.2 | D31: BLENDER | E31: BC.2-S1, BC.3-S2, BC.3-S3, BC.3-S6 | F31: =LEN(E31)-LEN(SUBSTITUTE(E31,",",""))+1 -> 4 | G31: Precision joint work; 'always returned to its stand' is a safety beat | H31: 6k | I31: 1K + emissive tip | J31: 1 | K31: 1.5 | L31: Med
A32: B28 | B32: Hot air rework station + nozzle | C32: BC.2 | D32: BLENDER | E32: BC.2-S1, BC.3-S2, BC.3-S3, BC.3-S4, BC.3-S5, BC.3-S6 | F32: =LEN(E32)-LEN(SUBSTITUTE(E32,",",""))+1 -> 6 | G32: The primary instrument in 5 of the 6 fixes | H32: 10k | I32: 1K + digital display | J32: 1 | K32: 2 | L32: Med | M32: Nozzle must be a separate child object - it is what the learner aims.
A33: B29 | B33: ESD-safe precision tweezers | C33: BC.2 | D33: BLENDER | E33: BC.2-S1, BC.3-S3, BC.3-S5, BC.3-S6 | F33: =LEN(E33)-LEN(SUBSTITUTE(E33,",",""))+1 -> 4 | G33: Places the new part - a manipulator, not scenery | H33: 2k | I33: 512 shared | J33: 1 | K33: 0.75 | L33: Low
A34: B30 | B34: Fume extractor arm | C34: BC.2 | D34: BLENDER | E34: BC.2-S1 | F34: =LEN(E34)-LEN(SUBSTITUTE(E34,",",""))+1 -> 1 | G34: 'Running before you ever pick up the iron' - safety framing | H34: 7k | I34: 1K | J34: 0 | K34: 1.5 | L34: Med
A35: B31 | B35: Spare parts tray | C35: BC.2 | D35: BLENDER | E35: BC.2-S1, BC.3-S2, BC.3-S3, BC.3-S6 | F35: =LEN(E35)-LEN(SUBSTITUTE(E35,",",""))+1 -> 4 | G35: Where the replacement part comes from | H35: 2k | I35: 512 shared | J35: 0 | K35: 0.5 | L35: Low
A36: B32 | B36: Workbench surface + studio lighting rig | C36: BC.2 | D36: BLENDER | E36: BC.2-S1, BC.2-S2, BC.3-S1, BC.3-S2, BC.3-S3, BC.3-S4, BC.3-S5, BC.3-S6, BC.3-S7 | F36: =LEN(E36)-LEN(SUBSTITUTE(E36,",",""))+1 -> 9 | G36: Shared set. Build the lighting once so every scene matches | H36: 2k | I36: 2K tileable + HDRI | J36: 0 | K36: 1.5 | L36: Med | M36: One lighting rig for the whole course = visual consistency for free.
A37: B33 | B37: Liquid flux bottle + fine brush cap | C37: BC.2 | D37: BLENDER | E37: BC.2-S2, BC.3-S4, BC.3-S5 | F37: =LEN(E37)-LEN(SUBSTITUTE(E37,",",""))+1 -> 3 | G37: 'Used TWICE in almost every rework job' - learner reaches for it constantly | H37: 2k | I37: 1K label | J37: 0 | K37: 0.75 | L37: Low | M37: Lathe/revolve geometry. The label texture does all the work.
A38: B34 | B38: Desoldering wick spool | C38: BC.2 | D38: BLENDER | E38: BC.2-S2, BC.3-S2, BC.3-S3, BC.3-S6 | F38: =LEN(E38)-LEN(SUBSTITUTE(E38,",",""))+1 -> 4 | G38: Pad cleaning step in 3 fixes | H38: 2k | I38: 512 + braid normal | J38: 0 | K38: 0.5 | L38: Low
A39: B35 | B39: Solder wire reel | C39: BC.2 | D39: BLENDER | E39: BC.2-S2, BC.3-S2, BC.3-S3, BC.3-S6 | F39: =LEN(E39)-LEN(SUBSTITUTE(E39,",",""))+1 -> 4 | G39: Forms every new joint | H39: 2k | I39: 512 | J39: 0 | K39: 0.5 | L39: Low
A40: B36 | B40: IPA bottle + lint-free swabs | C40: BC.2 | D40: BLENDER | E40: BC.2-S2, BC.3-S1, BC.3-S3, BC.3-S4 | F40: =LEN(E40)-LEN(SUBSTITUTE(E40,",",""))+1 -> 4 | G40: Pad cleaning in 4 places | H40: 2k | I40: 1K label | J40: 0 | K40: 0.75 | L40: Low
A41: B37 | B41: UV-curable solder mask bottle + UV lamp | C41: BC.2 | D41: BLENDER | E41: BC.2-S2 | F41: =LEN(E41)-LEN(SUBSTITUTE(E41,",",""))+1 -> 1 | G41: 'Green oil' - distinctive, learners must recognise it | H41: 4k | I41: 1K label + emissive | J41: 1 | K41: 1 | L41: Low
...

Sheet Blender Build List
A1: Blender build list - 3D assets, animation clips and baked effects
A2: Sequenced. Build the master assets in Wave 1; every later scene reuses them.
A4: Wave | B4: Asset ID | C4: Asset name | D4: Tri budget | E4: Textures | F4: Anim clips | G4: Est. days | H4: Complexity | I4: Build notes
A5: WAVE 1 - master assets (everything else depends on these)
B6: B02 | C6: Mainboard (PBA) - populated | D6: 45k | E6: 2K colour + 1K rough/normal | F6: 0 | G6: 4 | H6: High | I6: MASTER ASSET - highest reuse in the whole course. Build once, texture properly, never rebuild.
B7: B01 | C7: Phone body shell + removable back cover | D7: 18k | E7: 2x1K PBR | F7: 0 | G7: 3 | H7: Med | I7: Model one generic mid-range Android form factor. Back cover as separate mesh so it can be lifted.
B8: B05 | C8: USB-C female port assembly (shell, insert, 24 pins, mounting legs, gasket) | D8: 30k | E8: 2K + gold/steel PBR | F8: 2 | G8: 4 | H8: High | I8: Build as 5 named sub-objects so explode + pin highlight are driven by transforms, not separate models.
B9: B10 | C9: FPC flex ribbon (rigged for bend + peel) | D9: 6k | E9: 1K gold/polyimide | F9: 2 | G9: 3 | H9: High | I9: Bone chain or shape keys. Cloth sim will NOT export to real-time - bake it.
B10: B11 | C10: Board-side ZIF socket + hinged flap + gold pins | D10: 14k | E10: 2K gold/black nylon | F10: 2 | G10: 4 | H10: High | I10: Flap on its own pivot. Latched/unlatched are two states the quiz can test.
B11: B32 | C11: Workbench surface + studio lighting rig | D11: 2k | E11: 2K tileable + HDRI | F11: 0 | G11: 1.5 | H11: Med | I11: One lighting rig for the whole course = visual consistency for free.
C12: Wave subtotal | G12: =SUM(G6:G11) -> 19.5
A14: WAVE 2 - remaining charging-path hardware
B15: B03 | C15: Sub-PBA / small daughterboard | D15: 8k | E15: 1K shared atlas | F15: 0 | G15: 1 | H15: Low | I15: Storyboard NOTE says the ribbon may bond to a Sub-PBA instead - needs its own mesh
B16: B04 | C16: Screw set + labelled screw tray | D16: 4k | E16: 512 shared | F16: 0 | G16: 1 | H16: Low | I16: Tray slot labels as a texture, not geometry.
B17: B06 | C17: USB-C male plug (cable end) | D17: 6k | E17: 1K shared | F17: 0 | G17: 1 | H17: Low | I17: Insertion + orientation demo
B18: B07 | C18: USB-C cable (curve-deformable) | D18: 3k | E18: 512 tileable | F18: 1 | G18: 1 | H18: Low | I18: Curve modifier, baked to skinned mesh for glTF export.
B19: B08 | C19: Wall charger adapter (TA) | D19: 5k | E19: 1K | F19: 0 | G19: 1 | H19: Low | I19: Start of the charging path; also the 'known-good TA' in every test step
B20: B09 | C20: Wall outlet / socket plate | D20: 1k | E20: 512 shared | F20: 0 | G20: 0.5 | H20: Low | I20: Anchors the path diagram in something familiar
B21: B12 | C21: Stiffener backing + anchoring solder pads | D21: 2k | E21: shares B11 atlas | F21: 0 | G21: 0.5 | H21: Low | I21: Named failure point (cracked/dry pads)
B22: B13 | C22: Charger IC package + BGA solder ball array | D22: 5k | E22: 1K | F22: 1 | G22: 2 | H22: Med | I22: Model the ball array. Cold-joint vs reflowed is a geometry+material variant, see B40.
B23: B14 | C23: Neighbouring SMT component kit (caps, resistors, shields) | D23: 6k | E23: 512 atlas | F23: 0 | G23: 1.5 | H23: Low | I23: Library of ~10 parts, instanced across the board. Cheap, big realism win.
B24: B15 | C24: Battery connector SOCKET (AXF361500, board side) | D24: 10k | E24: 2K gold plating | F24: 1 | G24: 2 | H24: Med | I24: Gold-plating texture detail is what sells this shot. Worth a proper anisotropic material.
B25: B16 | C25: Battery connector HEADER (AXF461500, battery side) | D25: 8k | E25: shares B15 atlas | F25: 1 | G25: 2 | H25: Med | I25: The mating half - two-part connector is the teaching point
B26: B17 | C26: Li-po battery pouch + tabs + BMS flex | D26: 7k | E26: 2K aluminium laminate | F26: 1 | G26: 2 | H26: Med | I26: Disconnect-first safety rule acts on this object
C27: Wave subtotal | G27: =SUM(G15:G26) -> 15.5
A29: WAVE 3 - bench tools and consumables (parallelisable, low risk)
B30: B18 | C30: Digital multimeter + probe leads | D30: 9k | E30: 1K + dynamic LCD | F30: 2 | G30: 2 | H30: Med | I30: LCD is a separate material slot driven at runtime (see U02), NOT a baked number.
B31: B19 | C31: USB power meter dongle | D31: 4k | E31: 1K + dynamic display | F31: 0 | G31: 1 | H31: Low | I31: Reads the actual current - the 'is it charging slowly' test
B32: B20 | C32: Magnifying lamp | D32: 4k | E32: 1K shared bench atlas | F32: 0 | G32: 1 | H32: Low | I32: Named in Fix 1 step 2
B33: B21 | C33: Digital (Dino) microscope | D33: 6k | E33: 1K shared bench atlas | F33: 0 | G33: 1.5 | H33: Med | I33: 'Inspect under magnification' recurs in 5 of 6 fixes
B34: B22 | C34: Precision screwdriver set | D34: 3k | E34: 512 shared | F34: 0 | G34: 1 | H34: Low | I34: Opening the phone
B35: B23 | C35: Plastic pry tools / spudger set | D35: 2k | E35: 512 shared | F35: 0 | G35: 0.5 | H35: Low | I35: Opening the phone without damage
B36: B24 | C36: Anti-static wrist band | D36: 2k | E36: 512 shared | F36: 0 | G36: 0.5 | H36: Low | I36: ESD discipline - visible on the bench
B37: B25 | C37: Anti-static mat | D37: 0.5k | E37: 1K tileable | F37: 0 | G37: 0.25 | H37: Low | I37: Bench surface for every repair scene
B38: B26 | C38: PBA holder / board fixture (articulated) | D38: 8k | E38: 1K | F38: 1 | G38: 2 | H38: Med | I38: Jaws need to open/close if you want the 'clamp the board' beat.
B39: B27 | C39: Soldering iron + stand | D39: 6k | E39: 1K + emissive tip | F39: 1 | G39: 1.5 | H39: Med | I39: Precision joint work; 'always returned to its stand' is a safety beat
B40: B28 | C40: Hot air rework station + nozzle | D40: 10k | E40: 1K + digital display | F40: 1 | G40: 2 | H40: Med | I40: Nozzle must be a separate child object - it is what the learner aims.
B41: B29 | C41: ESD-safe precision tweezers | D41: 2k | E41: 512 shared | F41: 1 | G41: 0.75 | H41: Low | I41: Places the new part - a manipulator, not scenery
... B50: B39 | C50: SUS-tip cleaning stick + alcohol swab | D50: 1k | E50: 512 | F50: 1 | G50: 0.5 | H50: Low | I50: THE tool for Fix 1, 'never a random sharp object'
C51: Wave subtotal | G51: =SUM(G30:G50) -> 20.5
...

Sheet Infographic List
A1: Infographic list - what should NOT be modelled in 3D
A2: Every item here is invisible signal flow, electrical logic, a number, a sequence or a comparison.
A4: Asset ID | B4: Graphic name | C4: Module | D4: Scenes used in | E4: Why 2D beats 3D here | F4: Output spec | G4: Est. days | H4: Source image
A5: I01 | B5: Charging path system diagram (Wall > Cable > Port > IC > Battery) | C5: BC.1 | D5: BC.1-S1 | E5: A causal chain, not an object. 3D adds nothing; a clean 2D chain is the mental model | F5: 0 | G5: 0.5 | H5: Vector / illustration, no 3D source needed
A6: I02 | B6: The three common problems card (no charge / slow / intermittent) | C6: BC.1 | D6: BC.1-S1, BC.3-S1 | E6: A taxonomy - text and icons | F6: 0 | G6: 0.25 | H6: Vector / illustration, no 3D source needed
A7: I03 | B7: USB-C pin function table (Row A / Row B contacts) | C7: BC.1 | D7: BC.1-S2 | E7: It is literally a table. Modelling 24 labelled pins in 3D to read a table wastes days | F7: 0 | G7: 0.5 | H7: Vector, from USB-C spec
A8: I04 | B8: USB-C signal trace overlay (VBUS / GND / CC1-CC2 / D+- / SBU) | C8: BC.1 | D8: BC.1-S2 | E8: Electrical signal paths are INVISIBLE inside the part. No 3D geometry exists to model | F8: 0 | G8: 0.75 | H8: Vector overlay, sits on live B05
A9: I05 | B9: USB-C reversibility explainer (flip the plug, one row lines up) | C9: BC.1 | D9: BC.1-S2 | E9: 'Rows A and B are electrical mirrors' is a logical relationship, best as a 2-state diagram | F9: 0 | G9: 0.5 | H9: Vector / illustration, no 3D source needed
A10: I06 | B10: Port component callout labels (9 named parts) | C10: BC.1 | D10: BC.1-S2 | E10: Leader lines + names, drawn over the 3D render | F10: 0 | G10: 0.5 | H10: Overlay on B05 render
A11: I07 | B11: IFC layered cross-section (latch / pins / FPC / stiffener / pads) | C11: BC.1 | D11: BC.1-S3 | E11: A stack-up you cannot see even with the part in hand | F11: 0 | G11: 0.75 | H11: Vector / illustration, no 3D source needed
A12: I08 | B12: IFC circuit chain (Port > flex tail > IFC socket > PBA traces) | C12: BC.1 | D12: BC.1-S3 | E12: Storyboard asks for it explicitly as a circuit diagram overlay | F12: 0 | G12: 0.5 | H12: Vector / illustration, no 3D source needed
A13: I09 | B13: Charger IC internal block diagram (OVP > buck > current sense > output, + I2C + thermal) | C13: BC.1 | D13: BC.1-S4 | E13: MUST be 2D. These are functional stages inside silicon - there is no visible geometry to model | F13: 0 | G13: 1 | H13: Vector / illustration, no 3D source needed
A14: I10 | B14: Charger IC pin / stage callouts | C14: BC.1 | D14: BC.1-S4 | E14: Labels over the 3D chip | F14: 0 | G14: 0.5 | H14: Overlay on B13 render
A15: I11 | B15: Battery connector spec card (2.40mm / 1.80mm, part numbers) | C15: BC.1 | D15: BC.1-S5 | E15: Dimension arrows and part numbers are annotation over a render, not geometry | F15: 0 | G15: 0.5 | H15: Overlay on B15 + B16 render
A16: I12 | B16: Battery + BMS protection callouts (PTC, SCP IC, BSI/TH, OVP, UVP) | C16: BC.1 | D16: BC.1-S6 | E16: Protection ICs on the BMS strip are too small to read in 3D and are identified by name, not shape | F16: 0 | G16: 0.75 | H16: Traced from supplied photo P03
... A32: I28 | B32: Fix-selection escalation ladder (Fix 1 > Fix 6, cheapest first) | C32: BC.3 | D32: BC.3-S1, BC.3-S7 | E32: 'Check each part one by one, starting with the easiest' is the whole method | F32: 0 | G32: 0.5 | H32: Vector / illustration, no 3D source needed
B34: INFOGRAPHIC TOTAL | G34: =SUM(G5:G32) -> 21
B36: Amber rows (I24, I28) are NOT in the storyboard - they are recommended additions. 1.25 days combined.
B37: Rule: every step strip and tool card uses a Blender render as its image. Same assets, second output channel.

Sheet Scene Map
A1: Scene map - what each of the 18 scenes needs
A2: Shows the reuse. Very little is built for a single scene.
A4: Scene | B4: Scene name | C4: What the storyboard asks for | D4: Blender assets | E4: Infographics | F4: Photo/Video | G4: Runtime
A5: BC.1-S1 | B5: How a Phone Charges | C5: Wall charger > cable > port > IC > battery, the whole path in 3D on a bench | D5: B01, B02, B05, B06, B07, B08, B09, B10, B17 | E5: I01, I02 | G5: U06
A6: BC.1-S2 | B6: The Charging Port | C6: Cutaway, 180 deg rotate, sequential pin highlight, exploded view | D6: B05, A01, A02 | E6: I03, I04, I05, I06
A7: BC.1-S3 | B7: The IFC Connector | C7: Flex ribbon route, ZIF flap open/close, contact pins | D7: B03, B10, B11, B12, A03, A04 | E7: I07, I08
A8: BC.1-S4 | B8: The Charger IC | C8: Macro zoom onto the chip + internal stage block diagram | D8: B02, B13, B14, A05 | E8: I09, I10
A9: BC.1-S5 | B9: The Battery Connector | C9: Photoreal macro of socket + header, then mated | D9: B15, B16, A06 | E9: I11 | F9: P02, V01
A10: BC.1-S6 | B10: The Battery | C10: Pouch, tabs, BMS protection callouts | D10: B17 | E10: I12 | F10: P03
A11: BC.1-S7 | B11: Quick Check | C11: MCQ - no visual asset | G11: U01, U07
A12: BC.2-S1 | B12: Tools on the Workbench | C12: Top-down labelled bench, 14 tools | D12: B18, B19, B20, B21, B22, B23, B24, B25, B26, B27, B28, B29, B30, B31, B32 | E12: I13, I15, I26 | G12: U03, U06
A13: BC.2-S2 | B13: Liquids & Consumables | C13: 8 bottles, spools and sticks | D13: B32, B33, B34, B35, B36, B37, B38, B39 | E13: I14 | G13: U03
A14: BC.2-S3 | B14: How to Use the Multimeter | C14: Probe placement at the port, then cable continuity | D14: B05, B06, B07, B18, A15 | E14: I15, I16 | F14: V02 | G14: U02
A15: BC.2-S4 | B15: Golden Safety Rule & Recap | C15: Disconnect the battery first | D15: B15, B16, B17, A06, A17 | E15: I25
A16: BC.3-S1 | B16: Fix 1 - Clean the charging port | C16: SUS stick in the slots, before/after dust | D16: B01, B05, B06, B20, B21, B25, B32, B36, B39, B41, B44, A14 | E16: I02, I17, I24, I28 | G16: U03, U04, U05, U06
A17: BC.3-S2 | B17: Fix 2 - Replace the port (metal box) | C17: Hot air desolder, pad clean, new port, tabs then pins | D17: B02, B05, B10, B14, B21, B26, B27, B28, B31, B32, B34, B35, B40, B41, B45, B46, B48, A07, A08, A17 | E17: I18, I25, I26, I27 | F17: V03 | G17: U04, U05
A18: BC.3-S3 | B18: Fix 3 - Replace the IFC ribbon | C18: Peel the flex, clean pads, one corner first | D18: B02, B03, B10, B11, B12, B26, B27, B28, B29, B31, B32, B34, B35, B36, B40, B42, B45, B46, B48, A04, A09, A10, A17 | E18: I19, I25, I26, I27 | G18: U04, U05
A19: BC.3-S4 | B19: Fix 4 - Reflow the Charger IC | C19: Reheat the BGA balls without lifting the chip | D19: B02, B13, B14, B26, B28, B32, B33, B36, B38, B40, B45, B46, B47, A11 | E19: I20 | G19: U04, U05
A20: BC.3-S5 | B20: Fix 5 - Replace the Charger IC | C20: Desolder, place, reflow under magnification | D20: B02, B13, B14, B26, B28, B29, B32, B33, B38, B40, B45, B46, B47, A12, A17 | E20: I21, I25 | F20: V04 | G20: U04, U05
A21: BC.3-S6 | B21: Fix 6 - Replace the battery connector | C21: Hot air, tape shield, new connector | D21: B02, B14, B15, B16, B18, B26, B27, B28, B29, B31, B32, B34, B35, B38, B40, B43, B45, B46, B48, A06, A13, A15, A17 | E21: I22, I25 | F21: P01 | G21: U02, U04
A22: BC.3-S7 | B22: Testing & Closing Up | C22: Reassemble, screws to tray slots, TA + USB test | D22: B01, B04, B06, B07, B08, B17, B18, B19, B22, B23, B25, B32, A16 | E22: I23, I24, I28 | G22: U02, U04, U07

Sheet Effort Summary
A1: Effort summary
A2: All figures are formulas over the Asset Register. Change a day estimate there and this updates.
A4: BY PRODUCTION ROUTE | G4: READING THIS SHEET
A5: Route | B5: Assets | C5: Anim clips | D5: Est. days | E5: % of days
A6: BLENDER | B6: =COUNTIF('Asset Register'!$D$5:$D$111,$A6) -> 65 | C6: =SUMIF('Asset Register'!$D$5:$D$111,$A6,'Asset Register'!$J$5:$J$111) -> 48 | D6: =SUMIF('Asset Register'!$D$5:$D$111,$A6,'Asset Register'!$K$5:$K$111) -> 87.5 | E6: =IFERROR(D6/$D$10,0) -> 0.71312143 | G6: The Blender share of effort is large but it buys the whole course, not one module - the
A7: INFOGRAPHIC | B7: =COUNTIF('Asset Register'!$D$5:$D$111,$A7) -> 28 | C7: =SUMIF('Asset Register'!$D$5:$D$111,$A7,'Asset Register'!$J$5:$J$111) -> 0 | D7: =SUMIF('Asset Register'!$D$5:$D$111,$A7,'Asset Register'!$K$5:$K$111) -> 21 | E7: =IFERROR(D7/$D$10,0) -> 0.17114914 | G7: master assets (B02 mainboard, B05 port, B10 flex, B11 ZIF socket) carry 18 scenes between them.
A8: PHOTO/VIDEO | B8: =COUNTIF('Asset Register'!$D$5:$D$111,$A8) -> 7 | C8: =SUMIF('Asset Register'!$D$5:$D$111,$A8,'Asset Register'!$J$5:$J$111) -> 0 | D8: =SUMIF('Asset Register'!$D$5:$D$111,$A8,'Asset Register'!$K$5:$K$111) -> 0.7 | E8: =IFERROR(D8/$D$10,0) -> 0.0057049715
A9: RUNTIME/CODE | B9: =COUNTIF('Asset Register'!$D$5:$D$111,$A9) -> 7 | C9: =SUMIF('Asset Register'!$D$5:$D$111,$A9,'Asset Register'!$J$5:$J$111) -> 0 | D9: =SUMIF('Asset Register'!$D$5:$D$111,$A9,'Asset Register'!$K$5:$K$111) -> 13.5 | E9: =IFERROR(D9/$D$10,0) -> 0.11002445 | G9: Infographics are a small fraction of the days and cover the content 3D genuinely cannot
A10: TOTAL | B10: =SUM(B6:B9) -> 107 | C10: =SUM(C6:C9) -> 48 | D10: =SUM(D6:D9) -> 122.7 | E10: =IFERROR(SUM(E6:E9),0) -> 1 | G10: reach: signal flow, chip-internal stages, spec numbers, ordered procedures, comparisons.
G12: Runtime/code is not an art cost and is under-scoped here on purpose - U04 (ordered-step
A13: BY MODULE | G13: validation) is the real core mechanic of BC.3 and deserves its own engineering estimate.
A14: Module | B14: Assets | C14: Anim clips | D14: Est. days | E14: % of days
A15: BC.1 | B15: =COUNTIF('Asset Register'!$C$5:$C$111,$A15) -> 40 | C15: =SUMIF('Asset Register'!$C$5:$C$111,$A15,'Asset Register'!$J$5:$J$111) -> 18 | D15: =SUMIF('Asset Register'!$C$5:$C$111,$A15,'Asset Register'!$K$5:$K$111) -> 51.05 | E15: =IFERROR(D15/$D$18,0) -> 0.41605542 | G15: The High-complexity rows are where schedule risk lives: B02, B05, B10, B11, B45, A09, A12, U02, U04.
A16: BC.2 | B16: =COUNTIF('Asset Register'!$C$5:$C$111,$A16) -> 34 | C16: =SUMIF('Asset Register'!$C$5:$C$111,$A16,'Asset Register'!$J$5:$J$111) -> 11 | D16: =SUMIF('Asset Register'!$C$5:$C$111,$A16,'Asset Register'!$K$5:$K$111) -> 35.6 | E16: =IFERROR(D16/$D$18,0) -> 0.29013855 | G16: Start those first and give them your strongest people.
A17: BC.3 | B17: =COUNTIF('Asset Register'!$C$5:$C$111,$A17) -> 33 | C17: =SUMIF('Asset Register'!$C$5:$C$111,$A17,'Asset Register'!$J$5:$J$111) -> 19 | D17: =SUMIF('Asset Register'!$C$5:$C$111,$A17,'Asset Register'!$K$5:$K$111) -> 36.05 | E17: =IFERROR(D17/$D$18,0) -> 0.29380603
A18: TOTAL | B18: =SUM(B15:B17) -> 107 | C18: =SUM(C15:C17) -> 48 | D18: =SUM(D15:D17) -> 122.7 | E18: =IFERROR(SUM(E15:E17),0) -> 1
A21: BY COMPLEXITY
A22: Complexity | B22: Assets | C22: Anim clips | D22: Est. days | E22: % of days
A23: Low | B23: =COUNTIF('Asset Register'!$L$5:$L$111,$A23) -> 63 | C23: =SUMIF('Asset Register'!$L$5:$L$111,$A23,'Asset Register'!$J$5:$J$111) -> 15 | D23: =SUMIF('Asset Register'!$L$5:$L$111,$A23,'Asset Register'!$K$5:$K$111) -> 39.2 | E23: =IFERROR(D23/$D$26,0) -> 0.3194784
A24: Med | B24: =COUNTIF('Asset Register'!$L$5:$L$111,$A24) -> 35 | C24: =SUMIF('Asset Register'!$L$5:$L$111,$A24,'Asset Register'!$J$5:$J$111) -> 20 | D24: =SUMIF('Asset Register'!$L$5:$L$111,$A24,'Asset Register'!$K$5:$K$111) -> 57.5 | E24: =IFERROR(D24/$D$26,0) -> 0.46862266
A25: High | B25: =COUNTIF('Asset Register'!$L$5:$L$111,$A25) -> 9 | C25: =SUMIF('Asset Register'!$L$5:$L$111,$A25,'Asset Register'!$J$5:$J$111) -> 13 | D25: =SUMIF('Asset Register'!$L$5:$L$111,$A25,'Asset Register'!$K$5:$K$111) -> 26 | E25: =IFERROR(D25/$D$26,0) -> 0.21189894
A26: TOTAL | B26: =SUM(B23:B25) -> 107 | C26: =SUM(C23:C25) -> 48 | D26: =SUM(D23:D25) -> 122.7 | E26: =IFERROR(SUM(E23:E25),0) -> 1
A29: CALENDAR VIEW
A30: Blender person-days | B30: =SUMIF('Asset Register'!$D$5:$D$111,"BLENDER",'Asset Register'!$K$5:$K$111) -> 87.5 | D30: Yellow cells are inputs - change the team size and the weeks recalculate.
A31: Blender artists assumed | B31: 3
A32: Blender calendar weeks (5-day week) | B32: =IFERROR(B30/B31/5,0) -> 5.8333333
A33: Infographic person-days | B33: =SUMIF('Asset Register'!$D$5:$D$111,"INFOGRAPHIC",'Asset Register'!$K$5:$K$111) -> 21
A34: Designers assumed | B34: 1
A35: Infographic calendar weeks | B35: =IFERROR(B33/B34/5,0) -> 4.2
A36: Runtime/code person-days | B36: =SUMIF('Asset Register'!$D$5:$D$111,"RUNTIME/CODE",'Asset Register'!$K$5:$K$111) -> 13.5
A37: Total person-days (all routes) | B37: =SUM('Asset Register'!$K$5:$K$111) -> 122.7
A38: Total distinct assets | B38: =COUNTA('Asset Register'!$A$5:$A$111) -> 107
A39: Total animation clips | B39: =SUM('Asset Register'!$J$5:$J$111) -> 48

Sheet Risks & Decisions
A1: Open decisions and schedule risks
A2: Settle the top four before anyone opens Blender.
A4: # | B4: Decision / risk | C4: Where it bites | D4: Options | E4: Recommendation | F4: Cost of getting it wrong | G4: Owner | H4: Decide by
A5: 1 | B5: Molten solder: real sim or baked? | C5: B45; every fix in BC.3 | D5: (a) Blender fluid sim, pre-rendered to video for that beat (b) baked vertex animation + animated emissive shader, stays interactive (c) skip the melt, cut straight to 'joint done' | E5: (b) for the fixes, (a) only for the one hero close-up in Fix 2. Never (c) - 'lift only once it liquifies' is the skill. | F5: Rework of 5 animation clips. ~8 days lost if discovered late. | G5: 3D lead | H5: Before Wave 4
A6: 2 | B6: Hands on screen, or tools only? | C6: Every BC.3 scene; storyboard says 'technician using...' | D6: (a) model + rig hands (b) tool-only convention, instrument moves with no hands (c) real video inserts for the hand-skill beats | E6: (b). Reads better at macro scale, it is what teardown videos do, and it saves 15-20 days plus constant clipping fixes. | F6: 15-20 days and a permanent clipping problem across every fix. | G6: Producer | H6: Before Wave 1
A7: 3 | B7: FPC ribbon deformation method | C7: B10, A09 - the peel-off in Fix 3 | D7: (a) Blender cloth sim (b) bone chain (c) shape keys (d) pre-rendered video | E7: (b) bone chain, baked to glTF. Cloth sim does not survive export. A09 cannot start until this rig signs off. | F7: A09 blocked. Fix 3 is the most misdiagnosed fault in the course - cannot ship it weak. | G7: 3D lead | H7: Before Wave 1
A8: 4 | B8: Runtime: extend the existing three.js stack, or Unity WebGL? | C8: Whole build | D8: (a) React + three.js, same as the welding sim (b) Unity WebGL (c) pre-rendered video + 2D interaction only | E8: (a) if the welding sim's runtime is reusable - you already have the shell, the language switcher and the step gating. | F8: A second engine means a second asset pipeline and no shared components. | G8: Eng lead | H8: Before Wave 1
A9: 5 | B9: Do the Charger IC internal stages get modelled? | C9: I09; BC.1-S4 | D9: (a) 2D block diagram (b) stylised 3D 'inside the chip' scene | E9: (a). OVP, buck converter and current sense are functional blocks in silicon with no visible geometry. The supplied reference already shows the right treatment. | F9: A week or more spent modelling something invented, that teaches less than the diagram. | G9: Instructional lead | H9: Before I09 starts
A10: 6 | B10: YouTube links: embed, license, or reshoot? | C10: V01-V04 | D10: (a) link out (b) license (c) reshoot on your own bench | E10: (c) for anything that ends up inside the assessed flow; (a) is fine for optional 'watch more'. | F10: Rights exposure on a government-facing TVET product. | G10: Content lead | H10: Before BC.3 review
A11: 7 | B11: Which handset does the 3D match? | C11: B01, B02 - and therefore everything | D11: (a) generic mid-range Android (b) match the realme unit in the supplied photos (c) several models | E11: (a) generic, but photographed alongside the real realme shots (P02) so learners can bridge. (c) triples the asset count. | F11: Learners trained on a board layout they never meet. Or 3x the modelling budget. | G11: Instructional lead | H11: Before Wave 1
A12: 8 | B12: Asset weight on low-end Android | C12: All Blender assets | D12: (a) budget from day one: Draco + KTX2, 8MB per scene ceiling (b) optimise at the end | E12: (a). Retrofitting compression across 51 assets is far more expensive than building to budget. | F12: A course that will not load on the devices it was built for. | G12: 3D lead | H12: Before Wave 1
A13: 9 | B13: Solder joint state set - in or out of scope? | C13: B40 | D13: (a) build all 5 states (b) good/bad only (c) skip | E13: (a). 1.5 days for the highest teaching value per day on the whole list - it is what makes the diagnosis assessable. | F13: No way to assess joint quality, which is most of the curriculum. | G13: Instructional lead | H13: Before Wave 4
A14: 10 | B14: Two missing graphics (I24 fault tree, I28 fix ladder) | C14: BC.3 as a whole | D14: (a) add both (b) leave the storyboard as written | E14: (a). 1.25 days combined. 'Start with the easiest thing first' is stated in the VO and never drawn. | F14: Learners memorise six fixes without a map for choosing between them. | G14: Instructional lead | H14: Before BC.3 design
B16: Amber rows are the four that block the start of modelling.
